Workbook

Sheet LJE 
A1: Emlpoyee Name | B1: Employee Type | C1: Department | D1: Job Position | E1: Manager | F1: Work Email | G1: Work Phone | H1: Private Email | I1: Private Phone | J1: Private Street | K1: Private Street2 | L1: Private Zip | M1: Private Country | N1: Bank Account/Account Number | O1: Bank Account/Bank | P1: Bank Account/Currency | Q1: Private Car Plate | R1: Nationality (Country) | S1: Identification No | T1: SSN No | U1: Passport No | V1: Gender | W1: Date of Birth | X1: Place of Birth | Y1: Country of Birth | Z1: Field of Study | AA1: Visa No | AB1: Visa Expiration Date | AC1: Work Permit No | AD1: Work Permit Expiration Date | AE1: Marital Status | AF1: Number of Dependent Children | AG1: Hourly Cost | AH1: Badge ID | AI1: Emergency Contact Name | AJ1: Emergency Contact Phone
A2: ABDULLAH HADI BIN HAZIUL KEFLI | B2: Employee | C2: SALES SERVICE | D2: TECHNICAL WORKER II | E2: TAN YI HUI | G2: 94771082 | J2: 1 WOODLANDS TERRACE | L2: 738471 | M2: Singapore | R2: Malaysian | S2: M3401812R | U2: A57518164 | V2: Male | W2: 36048 | Y2: MALAYSIA | AD2: NULL | AE2: Single | AF2: 0 | AG2: =VLOOKUP(D2,lookup!$A$2:$B$57,2,1) -> 21 | AH2: 0477 | AI2: NULL | AJ2: NULL
A3: AFRYJAMALDY BIN BAHTIAR | B3: Employee | C3: SALES SERVICE | D3: SR TECH WORKER III | E3: TAN YI HUI | G3: 88586215 | J3: 1 WOODLANDS TERRACE | L3: 738471 | M3: Singapore | R3: Malaysian | S3: G8807471N | U3: A61168554 | V3: Male | W3: 35692 | Y3: MALAYSIA | AD3: NULL | AE3: Single | AF3: 0 | AG3: =VLOOKUP(D3,lookup!$A$2:$B$57,2,1) -> 24 | AH3: 0265 | AI3: NULL | AJ3: NULL
A4: AGOTE LILIBETH | B4: Employee | C4: SALES OVERSEA | D4: SALES & BUSINESS DEVELOPMENT MANAGER | E4: YAP KAI CHONG | F4: lilibeth@lingjack.com | G4: 63 976 525 9679 | J4: 1 WOODLANDS TERRACE | L4: 738471 | M4: Singapore | R4: Filipino | U4: P5814232A | V4: Female | W4: 25921 | Y4: PHILIPPINES | AD4: NULL | AE4: Single | AF4: 0 | AG4: =VLOOKUP(D4,lookup!$A$2:$B$57,2,1) -> 0 | AH4: 0480 | AI4: NULL | AJ4: NULL
A5: ALAM MD TOUHID | B5: Employee | C5: CS | D5: DRIVER III | E5: QUAH GEOK EAN | G5: 80589815 | J5: 1 WOODLANDS TERRACE | L5: 738471 | M5: Singapore | R5: Bangladeshi | S5: G2031335N | U5: A17837145 | V5: Male | W5: 32426 | Y5: BANGLADESH | AD5: NULL | AE5: Married | AF5: 0 | AG5: =VLOOKUP(D5,lookup!$A$2:$B$57,2,1) -> 22 | AH5: 0456 | AI5: NULL | AJ5: NULL
A6: AUNG ZAW MIN | B6: Employee | C6: PRODUCTION | D6: PLANT MANAGER | E6: LIM KOK MENG | F6: aungzawmin@lingjack.com | G6: 83556072 | J6: BLK 448 JURONG WEST ST 42 #06-240 | L6: 640448 | M6: Singapore | R6: Myanmar | S6: G6133091M | U6: MH887710 | V6: Male | W6: 31666 | Y6: MYANMAR | AC6: 0 92281620 | AD6: 46389 | AE6: Married | AF6: 0 | AG6: =VLOOKUP(D6,lookup!$A$2:$B$57,2,1) -> 58 | AH6: 0468 | AI6: NGU WAR MYINT | AJ6: 96187552
A7: CAROL WOON CHEN HEONG | B7: Employee | C7: PROCUREMENT | D7: PURCHASING EXECUTIVE III | E7: LIM HONG MENG | F7: carolwoon@lingjack.com | G7: 83127004 | J7: BLK 337 SEMBAWANG CRESCENT #08-178 | L7: 750337 | M7: Singapore | R7: Singaporean | S7: S8560157A | U7: K2274904A | V7: Female | W7: 31085 | Y7: MALAYSIA | AD7: NULL | AE7: Married | AF7: 0 | AG7: =VLOOKUP(D7,lookup!$A$2:$B$57,2,1) -> 0 | AH7: 0313 | AI7: VIVIEN WOON KERK HEONG | AJ7: 91691158
A8: CHAI YANN YI | B8: Employee | C8: ACCOUNTS | D8: ACCOUNTS EXEC III | E8: TEYOH HUEY LING | F8: yannyichai@lingjack.com | G8: 81918112 | J8: BLK 694D WOODLANDS DR #12-90 | L8: 734694 | M8: Singapore | R8: Singaporean | S8: S9088044F | U8: K4101362G | V8: Female | W8: 32918 | Y8: MALAYSIA | AD8: NULL | AE8: Married | AF8: 0 | AG8: =VLOOKUP(D8,lookup!$A$2:$B$57,2,1) -> 0 | AH8: 0369 | AI8: CHANG SOON YEP | AJ8: 98737225
A9: CHAN SIEW PENG | B9: Employee | C9: ADMIN HR | D9: HR MANAGER | E9: HO KIAN TECK | F9: esther@lingjack.com | G9: 91271863 | J9: 29 LI HWAN CLOSE | L9: 557152 | M9: Singapore | R9: Singaporean | S9: S1438776E | U9: K4401890D | V9: Female | W9: 22006 | AD9: NULL | AE9: Single | AF9: 0 | AG9: =VLOOKUP(D9,lookup!$A$2:$B$57,2,1) -> 0 | AH9: 0010 | AI9: NULL | AJ9: NULL
A10: CHEN MANYING | B10: Employee | C10: CS | D10: CS EXEC III | E10: QUAH GEOK EAN | F10: wendychen@lingjack.com | G10: 84443859 | J10: BLK 515 JURONG WEST ST 52 #02-25 | L10: 640515 | M10: Singapore | R10: China | S10: G0853686X | U10: EE6836275 | V10: Female | W10: 36932 | Y10: CHINA | AC10: 0 79189952 | AD10: 46722 | AE10: Single | AF10: 0 | AG10: =VLOOKUP(D10,lookup!$A$2:$B$57,2,1) -> 0 | AH10: 0519 | AI10: NULL | AJ10: NULL
A11: CHEN QIJIANG | B11: Employee | C11: PRODUCTION | D11: PRODUCTION SPECIALIST II | E11: AUNG ZAW MIN | G11: 83856282 | J11: 1 WOODLANDS TERRACE | L11: 738471 | M11: Singapore | R11: China | S11: G5939387T | U11: E98378751 | V11: Male | W11: 27293 | Y11: CHINA | AD11: NULL | AE11: Married | AF11: 0 | AG11: =VLOOKUP(D11,lookup!$A$2:$B$57,2,1) -> 24 | AH11: 0204 | AI11: NULL | AJ11: NULL
A12: CHIN YI MIN | B12: Employee | C12: CS | D12: CS EXEC III | E12: QUAH GEOK EAN | F12: yiminchin@lingjack.com | G12: 84332388 | J12: APT BLK 782D WOODLANDS CRESCENT #15-345 | L12: 734782 | M12: Singapore | R12: Malaysian | S12: S9379199A | U12: A55263196 | V12: Female | W12: 34258 | Y12: MALAYSIA | AD12: NULL | AE12: Married | AF12: 0 | AG12: =VLOOKUP(D12,lookup!$A$2:$B$57,2,1) -> 0 | AH12: 0500 | AI12: NULL | AJ12: NULL
A13: CHONG SUK FANG | B13: Employee | C13: ACCOUNTS | D13: CLERK | E13: TEYOH HUEY LING | F13: acct08@lingjack.com | G13: 87971206 | J13: BLK 406 WOODLANDS ST 41 #07-10 | L13: 730406 | M13: Singapore | R13: Malaysian | S13: M3160687R | U13: A55291887 | V13: Female | W13: 36135 | Y13: MALAYSIA | AD13: NULL | AE13: Single | AF13: 0 | AG13: =VLOOKUP(D13,lookup!$A$2:$B$57,2,1) -> 0 | AH13: 0432 | AI13: NULL | AJ13: NULL
A14: DENG FANDONG | B14: Employee | C14: PRODUCTION | D14: LATHE SETTER-OPERATOR | E14: AUNG ZAW MIN | G14: 98933232 | J14: 1 WOODLANDS TERRACE | L14: 738471 | M14: Singapore | R14: China | S14: G2407645N | U14: EK9020153 | V14: Male | W14: 32848 | Y14: CHINA | AD14: NULL | AE14: Married | AF14: 0 | AG14: =VLOOKUP(D14,lookup!$A$2:$B$57,2,1) -> 19 | AH14: 0465 | AI14: NULL | AJ14: NULL
A15: DILESHNAIR CHANDRAN | B15: Employee | C15: PRODUCTION | D15: PRODUCTION WORKER I | E15: AUNG ZAW MIN | G15: 98114935 | J15: 1 WOODLANDS TERRACE | L15: 738471 | M15: Singapore | R15: Malaysian | S15: G2835152L | U15: A56111916 | V15: Male | W15: 34993 | AD15: NULL | AE15: Single | AF15: 0 | AG15: =VLOOKUP(D15,lookup!$A$2:$B$57,2,1) -> 18 | AH15: 0023 | AI15: NULL | AJ15: NULL
A16: EDEN LIM ZHI HENG | B16: Employee | C16: ENGINEERING | D16: INTERNSHIP STUDENT | E16: FUNG HOE ANN | G16: 83635935 | J16: APT BLK 411B FERNVALE ROAD #04-72 | L16: 792411 | M16: Singapore | R16: Singaporean | S16: T0572368F | V16: Male | W16: 38578 | Y16: SINGAPORE | AD16: NULL | AE16: Single | AF16: 0 | AG16: =VLOOKUP(D16,lookup!$A$2:$B$57,2,1) -> 0 | AH16: 0516 | AI16: NULL | AJ16: NULL
A17: FENG ZHANPENG | B17: Employee | C17: CS | D17: DRIVER III | E17: QUAH GEOK EAN | G17: 81531309 | J17: 1 WOODLANDS TERRACE | L17: 738471 | M17: Singapore | R17: China | S17: G2562867K | U17: EL0508351 | V17: Male | W17: 31040 | Y17: CHINA | AD17: NULL | AE17: Married | AF17: 0 | AG17: =VLOOKUP(D17,lookup!$A$2:$B$57,2,1) -> 22 | AH17: 0403 | AI17: NULL | AJ17: NULL
A18: FUNG HOE ANN | B18: Employee | C18: ENGINEERING | D18: SR ENGINEERING MGR | E18: LIM KOK KHENG | F18: lucas@lingjack.com | G18: 96683870 | J18: BLK 658 WOODLANDS RING RD #08-120 | L18: 730658 | M18: Singapore | R18: Singaporean | S18: S7105888C | U18: K2675016P | V18: Male | W18: 25985 | AD18: NULL | AE18: Married | AF18: 0 | AG18: =VLOOKUP(D18,lookup!$A$2:$B$57,2,1) -> 0 | AH18: 0030 | AI18: NULL | AJ18: NULL
A19: GOH CHIEW PENG DORIS | B19: Employee | C19: PROCUREMENT | D19: PURCHASING MGR | E19: LIM HONG MENG | F19: dorisgoh@lingjack.com | G19: 90049288 | J19: BLK 504B MONTREAL DR #10-38 | L19: 752504 | M19: Singapore | R19: Singaporean | S19: S7420342F | U19: K4289324Z | V19: Female | W19: 27202 | AD19: NULL | AE19: Married | AF19: 0 | AG19: =VLOOKUP(D19,lookup!$A$2:$B$57,2,1) -> 0 | AH19: 0033 | AI19: William Goh | AJ19: 98430858
A20: GU MINGHUI | B20: Employee | C20: PRODUCTION | D20: PRODUCTION SPECIALIST III | E20: AUNG ZAW MIN | G20: 80234623 | J20: 1 WOODLANDS TERRACE | L20: 738471 | M20: Singapore | R20: China | S20: G8628897X | U20: EC7440264 | V20: Male | W20: 35953 | AD20: NULL | AE20: Single | AF20: 0 | AG20: =VLOOKUP(D20,lookup!$A$2:$B$57,2,1) -> 24 | AH20: 0203 | AI20: NULL | AJ20: NULL
A21: HAFIZ AMINULLAH BIN AB HALIM | B21: Employee | C21: LOGISTIC | D21: STORE KEEPER II | E21: TAN KHEM HIOK | G21: 82630998 | J21: 1 WOODLANDS TERRACE | L21: 738471 | M21: Singapore | R21: Malaysian | S21: G7553885K | U21: A58256880 | V21: Male | W21: 30892 | AD21: NULL | AE21: Married | AF21: 0 | AG21: =VLOOKUP(D21,lookup!$A$2:$B$57,2,1) -> 19 | AH21: 0034 | AI21: NULL | AJ21: NULL
A22: HASAN MAHEDI | B22: Employee | C22: SALES SERVICE | D22: TECHNICAL WORKER I | E22: TAN YI HUI | G22: 93909915 | J22: 1 WOODLANDS TERRACE | L22: 738471 | M22: Singapore | R22: Bangladeshi | S22: G2592127K | U22: BW0700991 | V22: Male | W22: 33703 | Y22: BANGLADESH | AD22: NULL | AE22: Single | AF22: 0 | AG22: =VLOOKUP(D22,lookup!$A$2:$B$57,2,1) -> 21 | AH22: 0457 | AI22: NULL | AJ22: NULL
A23: HEW MEI LING | B23: Employee | C23: SALES LOCAL | D23: SALES MANAGER | E23: OW SIEW MAY | F23: meilinghew@lingjack.com | G23: 92320675 | J23: 1 WOODLANDS TERRACE | L23: 738471 | M23: Singapore | R23: Malaysian | S23: S8565078E | U23: A61516445 | V23: Female | W23: 31076 | AD23: NULL | AE23: D | AF23: 0 | AG23: =VLOOKUP(D23,lookup!$A$2:$B$57,2,1) -> 0 | AH23: 0036 | AI23: Hew Kim Chen | AJ23: +6014 2222988
A24: HTAN LAN KHAING | B24: Employee | C24: SALES OVERSEA | D24: SALES & BUSINESS DEVELOPMENT ENGINEER | E24: YAP KAI CHONG | F24: htanlankhaing@lingjack.com | G24: 959975913087 | J24: 1 WOODLANDS TERRACE | L24: 738471 | M24: Singapore | R24: Myanmar | U24: MG152074 | V24: Male | W24: 30346 | AD24: NULL | AE24: Married | AF24: 0 | AG24: =VLOOKUP(D24,lookup!$A$2:$B$57,2,1) -> 0 | AH24: 0285 | AI24: NULL | AJ24: NULL
A25: KANG BEE CHING | B25: Employee | C25: ADMIN HR | D25: SNR HR EXECUTIVE | E25: CHAN SIEW PENG | F25: beechingkang@lingjack.com | G25: 97547618 | J25: BLK 552 CHOA CHU KANG ST 52 #02-43 | L25: 680552 | M25: Singapore | R25: Singaporean | S25: S7170640J | U25: K3560105A | V25: Female | W25: 26089 | AD25: NULL | AE25: Married | AF25: 0 | AG25: =VLOOKUP(D25,lookup!$A$2:$B$57,2,1) -> 0 | AH25: 0043 | AI25: Law Han Soon | AJ25: 97771385
A26: KHAIRUL AMMAR BIN NORDIN | B26: Employee | C26: PRODUCTION | D26: PRODUCTION WORKER III | E26: AUNG ZAW MIN | G26: 601127322741 | J26: 1 WOODLANDS TERRACE | L26: 738471 | M26: Singapore | R26: Malaysian | S26: M3673705T | U26: A71314557 | V26: Male | W26: 37073 | Y26: MALAYSIA | AD26: NULL | AE26: Single | AF26: 0 | AG26: =VLOOKUP(D26,lookup!$A$2:$B$57,2,1) -> 18 | AH26: 0514 | AI26: NULL | AJ26: NULL
A27: KOELAMBA KRISHNAN | B27: Employee | C27: PRODUCTION | D27: SECTION LEADER | E27: AUNG ZAW MIN | G27: 97340944 | J27: BLK 401 WOODLANDS ST 41 #03-26 | L27: 730401 | M27: Singapore | R27: Malaysian | S27: F7686327W | U27: A62009296 | V27: Female | W27: 22230 | AD27: NULL | AE27: Single | AF27: 0 | AG27: =VLOOKUP(D27,lookup!$A$2:$B$57,2,1) -> 29 | AH27: 0046 | AI27: NULL | AJ27: NULL
A28: KOH LIAN WAH | B28: Employee | C28: QAQC | D28: ASST ENGINEER | E28: MARIMUTHU SURESH KUMAR | F28: alexkoh@lingjack.com | G28: 90262309 | J28: BLK 424D YISHUN AVE 11 #08-316 | L28: 764424 | M28: Singapore | R28: Singaporean | S28: S7134767B | U28: E4498714E | V28: Male | W28: 26201 | AD28: NULL | AE28: Married | AF28: 0 | AG28: =VLOOKUP(D28,lookup!$A$2:$B$57,2,1) -> 32 | AH28: 0047 | AI28: Vincent Koh | AJ28: 98517388
A29: KWA SHI YUN | B29: Employee | C29: CS | D29: SR CS EXEC | E29: QUAH GEOK EAN | F29: sharonkwa@lingjack.com | G29: 81397758 | J29: BLK 218 YISHUN ST 21 #11-353 | L29: 760218 | M29: Singapore | R29: Singaporean | S29: S9429108I | U29: K3940596Z | V29: Female | W29: 34558 | Y29: SINGAPORE | AD29: NULL | AE29: Single | AF29: 0 | AG29: =VLOOKUP(D29,lookup!$A$2:$B$57,2,1) -> 0 | AH29: 0364 | AI29: NULL | AJ29: NULL
A30: LEE YEN MAY | B30: Employee | C30: SALES LOCAL | D30: SALES EXECUTIVE III | E30: OW SIEW MAY | F30: yenmaylee@lingjack.com | G30: 86961357 | J30: 1 WOODLANDS TERRACE | L30: 738471 | M30: Singapore | R30: Malaysian | S30: M4341428X | U30: A62955271 | V30: Female | W30: 35727 | Y30: MALAYSIA | AD30: NULL | AE30: Married | AF30: 0 | AG30: =VLOOKUP(D30,lookup!$A$2:$B$57,2,1) -> 0 | AH30: 0454 | AI30: NULL | AJ30: NULL
A31: LEROY SOH YI XIONG | B31: Employee | C31: SALES OVERSEA | D31: SALES EXECUTIVE, REGIONAL | E31: YAP KAI CHONG | F31: leroysoh@lingjack.com | G31: 92373618 | J31: BLK 102 BUKIT PURMEI RD #03-66 | L31: 90102 | M31: Singapore | R31: Singaporean | S31: S9124156J | U31: K3364190H | V31: Male | W31: 33426 | Y31: SINGAPORE | AD31: NULL | AE31: D | AF31: 0 | AG31: =VLOOKUP(D31,lookup!$A$2:$B$57,2,1) -> 0 | AH31: 0502 | AI31: NULL | AJ31: NULL
A32: LIAW ZHU YIK | B32: Employee | C32: ENGINEERING | D32: ENGINEER | E32: FUNG HOE ANN | F32: zhuyikliaw@lingjack.com | G32: 91345774 | J32: BLK 214 LOR 8 TOA PAYOH #17-733 | L32: 310214 | M32: Singapore | R32: Malaysian | S32: S9580222B | U32: A70678317 | V32: Male | W32: 34700 | Y32: MALAYSIA | AD32: NULL | AE32: Single | AF32: 0 | AG32: =VLOOKUP(D32,lookup!$A$2:$B$57,2,1) -> 36 | AH32: 0209 | AI32: NULL | AJ32: NULL
A33: LIM AI ENG IVY | B33: Employee | C33: CS | D33: MANAGER | E33: QUAH GEOK EAN | F33: ivy@lingjack.com | G33: 94370137 | J33: BLK 237 YISHUN RING RD #03-1024 | L33: 760237 | M33: Singapore | R33: Singaporean | S33: S8209723F | U33: K4061651B | V33: Female | W33: 30052 | AD33: NULL | AE33: Married | AF33: 0 | AG33: =VLOOKUP(D33,lookup!$A$2:$B$57,2,1) -> 0 | AH33: 0055 | AI33: GOH CHEE LOON | AJ33: 94781983
A34: LIM HONG MENG | B34: Employee | C34: PROCUREMENT | D34: PURCHASING DIRECTOR | E34: LIM KOK KHENG | F34: hongmeng@lingjack.com | G34: 98270680 | J34: 6 JALAN DERUM | L34: 759419 | M34: Singapore | R34: Singaporean | S34: S7005351I | U34: K3899880R | V34: Female | W34: 25611 | AD34: NULL | AE34: Married | AF34: 0 | AG34: =VLOOKUP(D34,lookup!$A$2:$B$57,2,1) -> 0 | AH34: 0060 | AI34: Er Hwee Lin | AJ34: 96930361
A35: LIM KOK KHENG | B35: Employee | C35: MGT | D35: MANAGING DIRECTOR | E35: LIM HONG MENG | F35: kenneth@lingjack.com | G35: 96173941 | J35: 56 JLN KEMUNING | L35: 769778 | M35: Singapore | R35: Singaporean | S35: S7217561A | U35: K3808456B | V35: Male | W35: 26419 | AD35: NULL | AE35: Married | AF35: 0 | AG35: =VLOOKUP(D35,lookup!$A$2:$B$57,2,1) -> 0 | AH35: 0063 | AI35: Lim Swee Fong | AJ35: 96173941
A36: LIM KOK MENG | B36: Employee | C36: PRODUCTION | D36: PLANT DIRECTOR | E36: LIM KOK KHENG | F36: lawrencelim@lingjack.com | G36: 97390092 | J36: 2D JALAN KEMUNING | L36: 769725 | M36: Singapore | R36: Singaporean | S36: S7217560C | U36: K2296594A | V36: Male | W36: 26419 | AD36: NULL | AE36: Married | AF36: 0 | AG36: =VLOOKUP(D36,lookup!$A$2:$B$57,2,1) -> 0 | AH36: 0064 | AI36: NULL | AJ36: NULL
A37: LIM KOK SIONG | B37: Employee | C37: MGT | D37: EXE DIRECTOR | E37: LIM KOK KHENG | F37: koksiong@lingjack.com | G37: 97348586 | J37: 27 JlN LEGUNDI | L37: 759283 | M37: Singapore | R37: Singaporean | S37: S7104234J | U37: K2339084G | V37: Male | W37: 25964 | Y37: SINGAPORE | AD37: NULL | AE37: Married | AF37: 0 | AG37: =VLOOKUP(D37,lookup!$A$2:$B$57,2,1) -> 36 | AH37: 0352 | AI37: NULL | AJ37: NULL
A38: LIM MEI QI | B38: Employee | C38: SALES LOCAL | D38: SALES SUPPORT COORDINATOR | E38: OW SIEW MAY | F38: meiqilim@lingjack.com | G38: 80643631 | J38: 1 WOODLANDS TERRACE | L38: 738471 | M38: Singapore | R38: Malaysian | S38: M3246526Q | U38: A57112365 | V38: Female | W38: 35985 | AD38: NULL | AE38: Single | AF38: 0 | AG38: =VLOOKUP(D38,lookup!$A$2:$B$57,2,1) -> 0 | AH38: 0451 | AI38: NULL | AJ38: NULL
A39: LIM SUEI KIAT | B39: Employee | C39: MGT | D39: MANAGING DIRECTOR | E39: LIM KOK KHENG | G39: 96339400 | J39: 27 JLN LEGUNDI | L39: 759283 | M39: Singapore | R39: Singaporean | S39: S1059331Z | U39: K5609680B | V39: Male | W39: 15883 | AD39: NULL | AE39: Married | AF39: 0 | AG39: =VLOOKUP(D39,lookup!$A$2:$B$57,2,1) -> 0 | AH39: 0069 | AI39: NULL | AJ39: NULL
A40: LIN WUZHU | B40: Employee | C40: PRODUCTION | D40: PRODUCTION SPECIALIST I | E40: AUNG ZAW MIN | G40: 85558753 | J40: 1 WOODLANDS TERRACE | L40: 738471 | M40: Singapore | R40: China | S40: G7739664R | U40: EF1579610 | V40: Male | W40: 27827 | AD40: NULL | AE40: Married | AF40: 0 | AG40: =VLOOKUP(D40,lookup!$A$2:$B$57,2,1) -> 24 | AH40: 0072 | AI40: NULL | AJ40: NULL
...

Sheet LJ Fire
A1: Employee Name | B1: Employee Type | C1: Department | D1: Job Position | E1: Manager | F1: Work Email | G1: Work Phone | H1: Private Email | I1: Private Phone | J1: Private Street | K1: Private Street2 | L1: Private Zip | M1: Private Country | N1: Bank Account/Account Number | O1: Bank Account/Bank | P1: Bank Account/Currency | Q1: Private Car Plate | R1: Nationality (Country) | S1: Identification No | T1: SSN No | U1: Passport No | V1: Gender | W1: Date of Birth | X1: Place of Birth | Y1: Country of Birth | Z1: Field of Study | AA1: Visa No | AB1: Visa Expiration Date | AC1: Work Permit No | AD1: Work Permit Expiration Date | AE1: Marital Status | AF1: Number of Dependent Children | AG1: Hourly Cost | AH1: Badge ID | AI1: Contact Name | AJ1: Contact Phone
A2: CHAN KOK CHOONG | B2: Employee | C2: LJ FIRE | D2: EXECUTIVE DIRECTOR | E2: LIM KOK KHENG | F2: samchan@lingjack.com | G2: 97487489 | J2: 34 KEPPEL BAY DR #03-67 CARIBBEAN AT KEPPEL BAY | L2: 98652 | M2: Singapore | R2: Singaporean | S2: S7048029H | U2: K5451972B | V2: Male | W2: 25848 | AD2: NULL | AE2: Married | AF2: 0 | AG2: =VLOOKUP(D2,lookup!$A$2:$B$57,2,1) -> 36 | AH2: 0009 | AI2: NULL | AJ2: NULL
A3: PHUNG SUNG WANG STANLEY | B3: Employee | C3: LJ FIRE | D3: MANAGER | E3: CHAN KOK CHOONG | F3: stanleyphung@lingjack.com | G3: 98463930 | J3: BLK 209 TAMPINES ST 21 #03-1325 | L3: 520209 | M3: Singapore | R3: Singaporean | S3: S8116986A | U3: K2362609A | V3: Male | W3: 29748 | AD3: NULL | AE3: Single | AF3: 0 | AG3: =VLOOKUP(D3,lookup!$A$2:$B$57,2,1) -> 0 | AH3: 0092 | AI3: NULL | AJ3: NULL
A4: LIM KOK KHENG | B4: Employee | C4: MGT | D4: MANAGING DIRECTOR | E4: LIM HONG MENG | F4: kenneth@lingjack.com | G4: 96173941 | J4: 56 JLN KEMUNING | L4: 769778 | M4: Singapore | R4: Singaporean | S4: S7217561A | U4: K3808456B | V4: Male | W4: 26419 | AD4: NULL | AE4: Married | AF4: 0 | AG4: =VLOOKUP(D4,lookup!$A$2:$B$57,2,1) -> 0 | AH4: 0063 | AI4: Lim Swee Fong | AJ4: 96173941

Sheet LJD
A1: Employee Name | B1: Employee Type | C1: Department | D1: Job Position | E1: Manager | F1: Work Email | G1: Work Phone | H1: Private Email | I1: Private Phone | J1: Private Street | K1: Private Street2 | L1: Private Zip | M1: Private Country | N1: Bank Account/Account Number | O1: Bank Account/Bank | P1: Bank Account/Currency | Q1: Private Car Plate | R1: Nationality (Country) | S1: Identification No | T1: SSN No | U1: Passport No | V1: Gender | W1: Date of Birth | X1: Place of Birth | Y1: Country of Birth | Z1: Field of Study | AA1: Visa No | AB1: Visa Expiration Date | AC1: Work Permit No | AD1: Work Permit Expiration Date | AE1: Marital Status | AF1: Number of Dependent Children | AG1: Hourly Cost | AH1: Badge ID | AI1: Contact Name | AJ1: Contact Phone
A2: GANESAN A/L K SUPRAMANIAM | B2: Employee | C2: LJD | D2: CLEANER | E2: LIEW CHEN KIANG | G2: 82662120 | J2: 1 WOODLANDS TERRACE | L2: 738471 | M2: Singapore | R2: Malaysian | S2: F8048193N | U2: A55303330 | V2: Male | W2: 26374 | Y2: MA | AD2: NULL | AE2: Single | AF2: 0 | AG2: =VLOOKUP(D2,lookup!$A$2:$B$57,2,1) -> 0 | AH2: 0338 | AI2: NULL | AJ2: NULL
A3: LIEW CHEN KIANG | B3: Employee | C3: LJD | D3: SR MGR, PDT DEV'T | E3: LIM KOK KHENG | F3: adrianliew@lingjack.com | G3: 92702490 | J3: BLK 123 MCNAIR RD #13-17 | L3: 320123 | M3: Singapore | R3: Singaporean | S3: S7142055H | U3: E7010510N | V3: Male | W3: 26265 | Y3: SPR | AD3: NULL | AE3: Married | AF3: 0 | AG3: =VLOOKUP(D3,lookup!$A$2:$B$57,2,1) -> 0 | AH3: 0189 | AI3: NULL | AJ3: NULL
A4: LIM KOK KHENG | B4: Employee | C4: MGT | D4: MANAGING DIRECTOR | E4: LIM HONG MENG | F4: kenneth@lingjack.com | G4: 96173941 | J4: 56 JLN KEMUNING | L4: 769778 | M4: Singapore | R4: Singaporean | S4: S7217561A | U4: K3808456B | V4: Male | W4: 26419 | AD4: NULL | AE4: Married | AF4: 0 | AG4: =VLOOKUP(D4,lookup!$A$2:$B$57,2,1) -> 0 | AH4: 0063 | AI4: Lim Swee Fong | AJ4: 96173941

Sheet LJDT
A1: Employee Name | B1: Employee Type | C1: Department | D1: Job Position | E1: Manager | F1: Work Email | G1: Work Phone | H1: Private Email | I1: Private Phone | J1: Private Street | K1: Private Street2 | L1: Private Zip | M1: Private Country | N1: Bank Account/Account Number | O1: Bank Account/Bank | P1: Bank Account/Currency | Q1: Private Car Plate | R1: Nationality (Country) | S1: Identification No | T1: SSN No | U1: Passport No | V1: Gender | W1: Date of Birth | X1: Place of Birth | Y1: Country of Birth | Z1: Field of Study | AA1: Visa No | AB1: Visa Expiration Date | AC1: Work Permit No | AD1: Work Permit Expiration Date | AE1: Marital Status | AF1: Number of Dependent Children | AG1: Hourly Cost | AH1: Badge ID | AI1: Contact Name | AJ1: Contact Phone
A2: ARKAR KYAW | B2: Employee | C2: LJ DT | D2: RIGGER/CABLE SPLICER | E2: ER HWEE LIN | G2: 90554501 | J2: 1 WOODLANDS TERRACE | L2: 738471 | M2: Singapore | R2: Myanmar | S2: M3460658N | U2: MH674511 | V2: Male | W2: 33902 | Y2: MM | AD2: NULL | AE2: Single | AF2: 0 | AG2: 21 | AH2: 0482 | AI2: NULL | AJ2: NULL
A3: AUNG THIHA SOE | B3: Employee | C3: LJ DT | D3: TECHNICIAN I | E3: ER HWEE LIN | F3: jamesaung@lingjack.com | G3: 81938165 | J3: BLK 511 Woodlands Dr 14 #01-57 | L3: 730511 | M3: Singapore | R3: Myanmar | S3: G1481868K | U3: MG766688 | V3: Male | W3: 34105 | Y3: MM | AC3: 0 95036309 | AD3: 46799 | AE3: Single | AF3: 0 | AG3: 21 | AH3: 0398 | AI3: NULL | AJ3: NULL
A4: COSCA KENDRICK ANDREW JAVIER | B4: Employee | C4: LJ DT | D4: IT ENGINEER | E4: ER HWEE LIN | F4: kendrick@lingjack.com | G4: 89522657 | J4: BLK 362B SEMBAWANG CRESCENT #10-823 | L4: 752362 | M4: Singapore | R4: Filipino | S4: M4312328Q | U4: P2702884C | V4: Male | W4: 36221 | Y4: PH | AC4: 0 28481810 | AD4: 46796 | AE4: Single | AF4: 0 | AG4: 0 | AH4: 0441 | AI4: COSCA ANGELITA JAVIER | AJ4: +639178582982
A5: DALA JOHN PAUL BUHAIN | B5: Employee | C5: LJ DT | D5: SOFTWARE ENGINEER | E5: ER HWEE LIN | F5: jaypee@lingjack.com | G5: 88943684 | J5: BLK 153A LOR 1 TOA PAYOH #07-1161 | L5: 311153 | M5: Singapore | R5: Filipino | S5: G4041858Q | U5: P0681613B | V5: Male | W5: 36191 | Y5: PH | AC5: 0 28303785 | AD5: 46385 | AE5: Single | AF5: 0 | AG5: 0 | AH5: 0386 | AI5: NULL | AJ5: NULL
A6: ER HWEE LIN | B6: Employee | C6: LJ DT | D6: SNR MANAGER, ADVANCED TECHNOLOGY DIVISION | E6: LIM KOK KHENG | F6: hweelin.er@lingjack.com | G6: 96930361 | J6: 6 JAALN DERUM | L6: 759419 | M6: Singapore | R6: Singaporean | S6: S6806975J | U6: K2600496B | V6: Male | W6: 24858 | Y6: SP | AD6: NULL | AE6: Married | AF6: 0 | AG6: 0 | AH6: 0319 | AI6: NULL | AJ6: NULL
A7: ISLAM SHAFIQUL | B7: Employee | C7: LJ DT | D7: RIGGER/CABLE SPLICER | E7: ER HWEE LIN | F7: skshafiqul855@gmail.com | G7: 81723644 | J7: 1 WOODLANDS TERRACE | L7: 738471 | M7: Singapore | R7: Bangladeshi | S7: G6913730Q | U7: A14795428 | V7: Male | W7: 32022 | Y7: BAN | AD7: NULL | AE7: Single | AF7: 0 | AG7: 21 | AH7: 0478 | AI7: NULL | AJ7: NULL
A8: JOTHI SIVAGURUNATHAN | B8: Employee | C8: LJ DT | D8: RIGGER/CABLE SPLICER | E8: ER HWEE LIN | G8: 85106326 | J8: 1 WOODLANDS TERRACE | L8: 738471 | M8: Singapore | R8: Indian | S8: G7784597L | U8: Y1314801 | V8: Male | W8: 29037 | Y8: IN | AD8: NULL | AE8: Married | AF8: 0 | AG8: 21 | AH8: 0481 | AI8: NULL | AJ8: NULL
A9: LIAU WEI KAI | B9: Employee | C9: LJ DT | D9: HARDWARE ENGINEER | E9: ER HWEE LIN | F9: shaunliau@lingjack.com | G9: 91125651 | J9: BLK 55 GEYLANG BAHRU #12-3611 | L9: 330055 | M9: Singapore | R9: Singaporean | S9: S9307042I | U9: K2879507K | V9: Male | W9: 34029 | Y9: SP | AD9: NULL | AE9: Single | AF9: 0 | AG9: 0 | AH9: 0348 | AI9: NULL | AJ9: NULL
A10: LIM JUN HUI | B10: Employee | C10: LJ DT | D10: INTERNSHIP STUDENT | E10: ER HWEE LIN | G10: 82364014 | J10: BLK 475B UPPER SERANGOON CRESCENT #02-537 | L10: 532475 | M10: Singapore | R10: Singaporean | S10: T0036312F | V10: Male | W10: 36813 | Y10: SP | AD10: NULL | AE10: Single | AF10: 0 | AG10: 0 | AH10: 0506 | AI10: NULL | AJ10: NULL
A11: RETUTAR RYAN JAY CENAL | B11: Employee | C11: LJ DT | D11: SOFTWARE ENGINEER | E11: ER HWEE LIN | G11: 639487924888 | J11: 1 WOODLANDS TERRACE | L11: 738471 | M11: Singapore | R11: Filipino | U11: P1460058C | V11: Male | W11: 35413 | Y11: PH | AD11: NULL | AE11: Single | AF11: 0 | AG11: 0 | AH11: 0497 | AI11: NULL | AJ11: NULL
A12: SOO KAH FAI CHRIS | B12: Employee | C12: LJ DT | D12: MANAGER | E12: ER HWEE LIN | F12: chrissoo@lingjack.com | G12: 81231401 | J12: BLK 559 HOUGANG ST 51 #12-396 | L12: 530559 | M12: Singapore | R12: Singaporean | S12: S7136258B | U12: K4328483N | V12: Male | W12: 26229 | Y12: SP | AD12: NULL | AE12: Single | AH12: 0232 | AI12: NULL | AJ12: NULL
A13: TOE NAING PHONE ZAW | B13: Employee | C13: LJ DT | D13: RIGGER/CABLE SPLICER | E13: ER HWEE LIN | F13: toenaing@lingjack.com | G13: 84668344 | J13: BLK 786E WOODLANDS DRIVE 60 #07-13 | L13: 735786 | M13: Singapore | R13: Myanmar | S13: G3866377T | U13: MG387523 | V13: Male | W13: 33285 | Y13: MM | AC13: 0 94623820 | AD13: 45834 | AE13: Single | AH13: 0460 | AI13: NULL | AJ13: NULL
A14: LIM KOK KHENG | B14: Employee | C14: MGT | D14: MANAGING DIRECTOR | E14: LIM HONG MENG | F14: kenneth@lingjack.com | G14: 96173941 | J14: 56 JLN KEMUNING | L14: 769778 | M14: Singapore | R14: Singaporean | S14: S7217561A | U14: K3808456B | V14: Male | W14: 26419 | AD14: NULL | AE14: Married | AF14: 0 | AG14: =VLOOKUP(D14,lookup!$A$2:$B$57,2,1) -> 0 | AH14: 0063 | AI14: Lim Swee Fong | AJ14: 96173941

Sheet LJ Property
A1: Employee Name | B1: Employee Type | C1: Department | D1: Job Position | E1: Manager | F1: Work Email | G1: Work Phone | H1: Private Email | I1: Private Phone | J1: Private Street | K1: Private Street2 | L1: Private Zip | M1: Private Country | N1: Bank Account/Account Number | O1: Bank Account/Bank | P1: Bank Account/Currency | Q1: Private Car Plate | R1: Nationality (Country) | S1: Identification No | T1: SSN No | U1: Passport No | V1: Gender | W1: Date of Birth | X1: Place of Birth | Y1: Country of Birth | Z1: Field of Study | AA1: Visa No | AB1: Visa Expiration Date | AC1: Work Permit No | AD1: Work Permit Expiration Date | AE1: Marital Status | AF1: Number of Dependent Children | AG1: Hourly Cost | AH1: Badge ID | AI1: Contact Name | AJ1: Contact Phone
A2: LIM KOK SIONG | B2: Employee | C2: MGT | D2: EXE DIRECTOR | E2: LIM KOK KHENG | F2: koksiong@lingjack.com | G2: 97348586 | J2: 27 JlN LEGUNDI | L2: 759283 | M2: Singapore | R2: Singaporean | S2: S7104234J | U2: K2339084G | V2: Male | W2: 25964 | Y2: SINGAPORE | AD2: NULL | AE2: Married | AF2: 0 | AG2: =VLOOKUP(D2,lookup!$A$2:$B$57,2,1) -> 36 | AH2: 0352 | AI2: NULL | AJ2: NULL

Sheet LJ GreenTech
A1: Employee Name | B1: Employee Type | C1: Department | D1: Job Position | E1: Manager | F1: Work Email | G1: Work Phone | H1: Private Email | I1: Private Phone | J1: Private Street | K1: Private Street2 | L1: Private Zip | M1: Private Country | N1: Bank Account/Account Number | O1: Bank Account/Bank | P1: Bank Account/Currency | Q1: Private Car Plate | R1: Nationality (Country) | S1: Identification No | T1: SSN No | U1: Passport No | V1: Gender | W1: Date of Birth | X1: Place of Birth | Y1: Country of Birth | Z1: Field of Study | AA1: Visa No | AB1: Visa Expiration Date | AC1: Work Permit No | AD1: Work Permit Expiration Date | AE1: Marital Status | AF1: Number of Dependent Children | AG1: Hourly Cost | AH1: Badge ID | AI1: Contact Name | AJ1: Contact Phone
A2: LIM KOK KHENG | B2: Employee | C2: MGT | D2: MANAGING DIRECTOR | E2: LIM HONG MENG | F2: kenneth@lingjack.com | G2: 96173941 | J2: 56 JLN KEMUNING | L2: 769778 | M2: Singapore | R2: Singaporean | S2: S7217561A | U2: K3808456B | V2: Male | W2: 26419 | AD2: NULL | AE2: Married | AF2: 0 | AG2: =VLOOKUP(D2,lookup!$A$2:$B$57,2,1) -> 0 | AH2: 0063 | AI2: Lim Swee Fong | AJ2: 96173941

Sheet LJ Malaysia
A1: Employee Name | B1: Employee Type | C1: Department | D1: Job Position | E1: Manager | F1: Work Email | G1: Work Phone | H1: Private Email | I1: Private Phone | J1: Private Street | K1: Private Street2 | L1: Private Zip | M1: Private Country | N1: Bank Account/Account Number | O1: Bank Account/Bank | P1: Bank Account/Currency | Q1: Private Car Plate | R1: Nationality (Country) | S1: Identification No | T1: SSN No | U1: Passport No | V1: Gender | W1: Date of Birth | X1: Place of Birth | Y1: Country of Birth | Z1: Field of Study | AA1: Visa No | AB1: Visa Expiration Date | AC1: Work Permit No | AD1: Work Permit Expiration Date | AE1: Marital Status | AF1: Number of Dependent Children | AG1: Hourly Cost | AH1: Badge ID | AI1: Contact Name | AJ1: Contact Phone
A2: ANIS EDDYFAZWAN BIN ABD SALIM | B2: Employee | C2: PRODUCTION DEPT | D2: ENGINEERING MANAGER | E2: NG SENG CHUAN | F2: ljm-engrg01@lingjack.com | G2: 016 8253321 | J2: No. 5 Jalan Api-api 3, Taman Megah Ria, Masai,Johor. | L2: 81750 | M2: Malaysia | R2: Malaysian | S2: 920726-12-5649 | V2: M | W2: 1992-07-26 00:00:00.000 | Y2: MA | AE2: M | AH2: L024 | AI2: NULL | AJ2: NULL
A3: ANIS NABILAH BINTI MOHD NOOR | B3: Employee | C3: PRODUCTION DEPT | D3: QUALITY CONTROL | E3: NG SENG CHUAN | G3: 177186091 | J3: NO.A-42 JALAN TERATAI, FELDA ULU TEBRAU, ULU TIRAM,JOHOR. | L3: 81810 | M3: Malaysia | R3: Malaysian | S3: 911119-01-6032 | V3: F | W3: 1991-11-19 00:00:00.000 | Y3: MA | AE3: D | AH3: L042 | AI3: NULL | AJ3: NULL
A4: AUNG ZAW LIN | B4: Employee | C4: PRODUCTION DEPT | D4: ASSEMBLE | E4: NG SENG CHUAN | G4: 1170234722 | J4: NO. 1 & 3 JALAN MAHIR 5, TAMAN PERIND. CEMERLANG, ULU TIRAM,JOHOR. | L4: 81800 | M4: Malaysia | R4: Myanmar | U4: MH795696 | V4: M | W4: 1984-09-11 00:00:00.000 | Y4: MM | AE4: M | AH4: M059 | AI4: NULL | AJ4: NULL
A5: AYE LWIN | B5: Employee | C5: PRODUCTION DEPT | D5: ASSEMBLE | E5: NG SENG CHUAN | G5: '011 61394054 | J5: NO. 1 & 3 JALAN MAHIR 5, TAMAN PERINDUSTRIAN CEMERLANG, | L5: 81800 | M5: Malaysia | R5: Myanmar | U5: MI311679 | V5: M | W5: 1985-05-09 00:00:00.000 | Y5: MM | AE5: M | AH5: M052 | AI5: U THAUNG | AJ5: 9772134201
A6: AYE LWIN | B6: Employee | C6: PRODUCTION DEPT | D6: ASSEMBLE | E6: NG SENG CHUAN | G6: ' 011 61393917 | J6: NO. 1 & 3 JALAN MAHIR 5, TAMAN PERINDUSTRIAN CEMERLANG, | L6: 81800 | M6: Malaysia | R6: Myanmar | U6: MI311674 | V6: M | W6: 1985-06-30 00:00:00.000 | Y6: MM | AE6: M | AH6: M047 | AI6: U KYAW AUNG | AJ6: 8784476059
A7: AYE MIN TUN | B7: Employee | C7: PRODUCTION DEPT | D7: SAND MIXING | E7: NULL | J7: NO. 1 & 3 JALAN MAHIR 5, TAMAN PERINDUSTRIAN CEMERLANG,ULU TIRAM,JOHOR. | L7: 81800 | M7: Malaysia | R7: Myanmar | U7: MI196498 | V7: M | W7: 1986-07-20 00:00:00.000 | Y7: MM | AE7: M | AH7: M060 | AI7: NULL | AJ7: NULL
A8: AYE ZAW | B8: Employee | C8: PRODUCTION DEPT | D8: OPERATOR MACHINE | E8: LEE YIK SENG | G8: 011-27489213 | J8: NO 1 & 3 JALAN MAHIR 5, TAMAN PERINDUSTRIAN CEMERLANG, ULU TIRAM,JOHOR. | L8: 81800 | M8: Malaysia | R8: Myanmar | U8: MG148395 | V8: M | W8: 2004-05-05 00:00:00.000 | Y8: MM | AE8: S | AH8: M055 | AI8: NULL | AJ8: NULL
A9: CHAN SIEW PENG | B9: Employee | C9: ADMIN DEPT | D9: NULL | E9: NULL | F9: esther@lingjack.com | M9: Malaysia | R9: Singaporean | S9: S1438776E | V9: F | W9: 1960-03-31 00:00:00.000 | AE9: S | AH9: S005 | AI9: NULL | AJ9: NULL
A10: FOLONIA BINTI KAPITAN | B10: Employee | C10: ADMIN DEPT | D10: PURCHASING EXECUTIVE | E10: NG SENG CHUAN | F10: ljm-admin01@lingjack.com | G10: 011 31539523 | J10: NO. 38 JALAN KENANGA 1/8, TAMAN DESA CEMERLANG, ULU TIRAM, JOHOR. | L10: 81800 | M10: Malaysia | R10: Malaysian | S10: 890613-12-5840 | V10: F | W10: 1989-06-13 00:00:00.000 | Y10: MA | AE10: M | AH10: O004 | AI10: NULL | AJ10: NULL
A11: HAN HTAY WIN | B11: Employee | C11: PRODUCTION DEPT | D11: ASSEMBLE | E11: NG SENG CHUAN | G11: '011 61712488 | J11: NO. 1 & 3 JALAN MAHIR 5, TAMAN PERINDUSTRIAN CEMERLANG, ULU TIRAM,JOHOR. | L11: 81800 | M11: Malaysia | R11: Myanmar | U11: MG811308 | V11: M | W11: 2004-07-28 00:00:00.000 | Y11: MM | AE11: S | AH11: M051 | AI11: U KYAW LIN | AJ11: 9776831743
A12: KANG BEE CHING | B12: Employee | C12: ADMIN DEPT | D12: NULL | E12: NULL | F12: beechingkang@lingjack.com | G12: 97547618 | J12: 1 Woodlands Terrace | L12: 680552 | M12: Malaysia | R12: Singapore PR | S12: S7170640J | V12: F | W12: 1971-06-05 00:00:00.000 | AE12: M | AH12: S004 | AI12: NULL | AJ12: NULL
A13: KHIN MAUNG HTOO | B13: Employee | C13: PRODUCTION DEPT | D13: MELTER | E13: MANIT SENNOK | G13: '011 61394037 | J13: NO. 1 & 3 JALAN MAHIR 5, TAMAN PERINDUSTRIAN CEMERLANG, | L13: 81800 | M13: Malaysia | R13: Myanmar | U13: MG388078 | V13: M | W13: 1996-04-27 00:00:00.000 | Y13: MM | AE13: S | AH13: M053 | AI13: NULL | AJ13: NULL
A14: KYAW AUNG | B14: Employee | C14: PRODUCTION DEPT | D14: OPERATOR MACHINE | E14: LEE YIK SENG | G14: '011 61393957 | J14: NO. 1 & 3 JALAN MAHIR 5, TAMAN PERINDUSTRIAN CEMERLANG, | L14: 81800 | M14: Malaysia | R14: Myanmar | U14: MG260359 | V14: M | W14: 1997-03-02 00:00:00.000 | Y14: MM | AE14: S | AH14: M049 | AI14: U MYA NYUNT | AJ14: 9448211137
A15: KYAW ZIN SOE | B15: Employee | C15: PRODUCTION DEPT | D15: MELTER | E15: MANIT SENNOK | G15: '011 61394012 | J15: NO. 1 & 3 JALAN MAHIR 5, TAMAN PERINDUSTRIAN CEMERLANG, ULU TIRAM,JOHOR. | L15: 81800 | M15: Malaysia | R15: Myanmar | U15: MG178975 | V15: M | W15: 1988-07-18 00:00:00.000 | Y15: MM | AE15: M | AH15: M046 | AI15: U MAUNG GYI | AJ15: 9755836650
A16: LEE YIK SENG | B16: Employee | C16: PRODUCTION DEPT | D16: PRODUCTION SUPERVISOR | E16: NG SENG CHUAN | G16: 014 6185891 | J16: NO 462 JALAN ANGGERIK, SIMPANG RENGGAM, JOHOR. | L16: 86200 | M16: Malaysia | R16: Malaysian | S16: 810129-01-5751 | V16: M | W16: 1981-01-29 00:00:00.000 | Y16: MA | AE16: D | AH16: L004 | AI16: NULL | AJ16: NULL
A17: LIM KOK KHENG (LIN GUOQING) | B17: Employee | C17: MGT | D17: EXECUTIVE DIRECTOR | E17: NULL | F17: kenneth@lingjack.com | G17: 006 596173941 | J17: NO 1 & 3 JALAN MAHIR 5 TAMAN PERINDUSTRIAN CEMERLANG, ULU TIRAM, JOHOR | L17: 81800 | M17: Malaysia | R17: Singaporean | U17: K3808456B | V17: M | W17: 1972-04-30 00:00:00.000 | Y17: OT | AE17: M | AH17: S002 | AI17: NULL | AJ17: NULL
A18: LIM KOK MENG (LIN GEMING) | B18: Employee | C18: MGT | D18: EXECUTIVE DIRECTOR | E18: NULL | F18: lawrencelim@lingjack.com | G18: 0065 97390092 | J18: NO 1 & 3 JALAN MAHIR 5, TAMAN PERINDUSTRIAN CEMERLANG, ULU TIRAM, JOHOR | L18: 81800 | M18: Malaysia | R18: Singaporean | U18: K2296594A | V18: M | W18: 1972-04-30 00:00:00.000 | Y18: SP | AE18: M | AH18: S003 | AI18: NULL | AJ18: NULL
A19: LIM SUEI KIAT | B19: Employee | C19: MGT | D19: EXECUTIVE DIRECTOR | E19: NULL | G19: 0065 96339400 | J19: NO 1 & 3 JALAN MAHIR 5 TAMAN PERINDUSTRIAN CEMERMERLANG, ULU TIRAM,JOHOR | L19: 81800 | M19: Malaysia | R19: Singaporean | U19: K1869251G | V19: M | W19: 1943-06-26 00:00:00.000 | Y19: SP | AE19: M | AH19: S001 | AI19: NULL | AJ19: NULL
A20: MANIT SENNOK | B20: Employee | C20: PRODUCTION DEPT | D20: MELTER | E20: NG SENG CHUAN | G20: 177401187 | J20: NO. 1 & 3 JALAN MAHIR 5, TAMAN PERINDUSTRIAN CEMERLANG, ULU TIRAM,JOHOR. | L20: 81800 | M20: Malaysia | R20: Thai | U20: AD0457811 | V20: M | W20: 1979-10-06 00:00:00.000 | Y20: TH | AE20: M | AH20: T004 | AI20: NULL | AJ20: NULL
A21: MAUNG SAN | B21: Employee | C21: PRODUCTION DEPT | D21: ASSEMBLE | E21: NULL | J21: NO 1 & 3 JALAN MAHIR 5, TAMAN PERINDUSTRIAN CEMERLANG, ULU TIRAM,JOHOR. | L21: 81800 | M21: Malaysia | R21: Myanmar | U21: MG219296 | V21: M | W21: 1988-06-16 00:00:00.000 | Y21: MM | AE21: M | AH21: M061 | AI21: NULL | AJ21: NULL
A22: MAY ZUN THU | B22: Employee | C22: PRODUCTION DEPT | D22: OPERATOR MACHINE | E22: NG SENG CHUAN | G22: 011 69863727 | J22: NO 1 & 3 JALAN MAHIR 5, TMN PERIND. CEMERLANG, ULU TIRAM, JOHOR. | L22: 81800 | M22: Malaysia | R22: Myanmar | U22: MD896708 | V22: F | W22: 1990-06-12 00:00:00.000 | Y22: MM | AE22: S | AH22: M036 | AI22: NULL | AJ22: NULL
A23: MIN MIN AUNG | B23: Employee | C23: PRODUCTION DEPT | D23: MOLDER | E23: NG SENG CHUAN | G23: 011 37474731 | J23: NO 1 & 3 JLN MAHIR 5, TMN PERINDUSTRIAN CEMERLANG, ULU TIRAM, JOHOR. | L23: 81800 | M23: Malaysia | R23: Myanmar | U23: MF235058 | V23: M | W23: 1990-05-07 00:00:00.000 | Y23: MM | AE23: M | AH23: M031 | AI23: NULL | AJ23: NULL
A24: MYO AUNG | B24: Employee | C24: PRODUCTION DEPT | D24: OPERATOR MACHINE | E24: LEE YIK SENG | G24: 018 3945308 | J24: NO. 1 & 3 JALAN MAHIR 5, TAMAN PERINDUSTRIAN CEMERLANG, | L24: 81800 | M24: Malaysia | R24: Myanmar | U24: MI311652 | V24: M | W24: 1987-05-28 00:00:00.000 | Y24: MM | AE24: S | AH24: M048 | AI24: NULL | AJ24: NULL
A25: MYO MIN HTET | B25: Employee | C25: PRODUCTION DEPT | D25: MELTER | E25: NG SENG CHUAN | G25: 018 7812948 | J25: NO 1 & 3 JALAN MAHIR 5, TMN PERIND. CEMERLANG, ULU TIRAM, JOHOR. | L25: 81800 | M25: Malaysia | R25: Myanmar | U25: MF896705 | V25: M | W25: 1997-10-02 00:00:00.000 | Y25: MM | AE25: M | AH25: M037 | AI25: NULL | AJ25: NULL
A26: NAING LIN | B26: Employee | C26: STORE DEPT | D26: STORE ASSISTANT | E26: NG SENG CHUAN | G26: 011 28985604 | J26: NO 1 & 3 JALAN MAHIR 5, TAMAN PERIND. CEMERLANG, ULU TIRAM, JOHOR. | M26: Malaysia | R26: Myanmar | U26: MF896709 | V26: M | W26: 1980-06-28 00:00:00.000 | Y26: MM | AE26: M | AH26: M014 | AI26: NULL | AJ26: NULL
A27: NG SENG CHUAN | B27: Employee | C27: ADMIN DEPT | D27: FACTORY MANAGER | E27: LIM KOK KHENG (LIN GUOQING) | F27: ng@lingjack.com | G27: 012 7877738 | J27: NO 49 JALAN JOHAR 7, TAMAN DESA CEMERLANG, ULU TIRAM, JOHOR. | L27: 81800 | M27: Malaysia | R27: Malaysian | S27: 720328-01-6133 | V27: M | W27: 1972-03-28 00:00:00.000 | Y27: MA | AE27: M | AH27: L001 | AI27: NULL | AJ27: NULL
A28: NG SIU HOON | B28: Employee | C28: ADMIN DEPT | D28: GENERAL CLERK | E28: NG SENG CHUAN | J28: NO 49 JLN JOHAR 7, TMN DESA CEMERLANG, ULU TIRAM,JOHOR | L28: 81800 | M28: Malaysia | R28: Malaysian | S28: 721127-01-5788 | V28: F | W28: 1972-11-21 00:00:00.000 | Y28: MA | AE28: M | AH28: L005 | AI28: NULL | AJ28: NULL
A29: NORIDAH BINTI MASWAN | B29: Employee | C29: ADMIN DEPT | D29: ADMIN EXECUTIVE | E29: NG SENG CHUAN | F29: noridah@lingjack.com | G29: 017 7435878 | J29: NO 03-12 BLK H, PANGSAPURI AKASIA, TAMAN DESA CEMERLANG, ULU TIRAM,JOHOR. | L29: 81800 | M29: Malaysia | R29: Malaysian | S29: 740724-01-6176 | V29: F | W29: 1974-07-24 00:00:00.000 | Y29: MA | AE29: M | AH29: O001 | AI29: NULL | AJ29: NULL
A30: NURUL AISYAH BINTI ABDUL RAHIM | B30: Employee | C30: ADMIN DEPT | D30: ASSISTANT PURCHASING EXE | E30: NG SENG CHUAN | F30: ljm-admin02lingjack.com | G30: 017 7863896 | J30: No. 05-12 BLOK A, FLAT AKASIA, TAMAN DESA CEMERLANG, ULU TIRAM,JOHOR. | L30: 81800 | M30: Malaysia | R30: Malaysian | S30: 951009-01-6476 | V30: F | W30: 1995-10-09 00:00:00.000 | Y30: MA | AE30: M | AH30: O006 | AI30: NULL | AJ30: NULL
A31: SAN WIN NAING | B31: Employee | C31: PRODUCTION DEPT | D31: ASSEMBLE | E31: NG SENG CHUAN | G31: '011 60544762 | J31: NO 1 & 3 JALAN MAHIR 5, TAMAN PERIND. CEMERLANG, ULU TIRAM, JOHOR. | M31: Malaysia | R31: Myanmar | U31: MG963220 | V31: M | W31: 1982-09-03 00:00:00.000 | Y31: MM | AE31: M | AH31: M006 | AI31: NULL | AJ31: NULL
A32: SANTHIA A/P MANOGARAN | B32: Employee | C32: STORE DEPT | D32: STORE SUPERVISOR | E32: NG SENG CHUAN | F32: ljm-store01@lingjack.com | G32: 016 7038223 | J32: NO 22 JALAN KERIS 27, TAMAN PUTRI WANGSA, ULU TIRAM, JOHOR | L32: 81800 | M32: Malaysia | R32: Malaysian | S32: 900327-01-6594 | V32: F | W32: 1990-03-27 00:00:00.000 | Y32: MA | AE32: M | AH32: L015 | AI32: NULL | AJ32: NULL
A33: SEIN KYAW HTAY | B33: Employee | C33: STORE DEPT | D33: STORE ASSISTANT | E33: SANTHIA A/P MANOGARAN | G33: 011-27489037 | J33: NO. 1 &3 JALAN MAHIR 5, TAMAN PERINDUSTRIAN CEMERLANG, ULU TIRAM,JOHOR. | L33: 81800 | M33: Malaysia | R33: Myanmar | U33: MG148390 | V33: M | W33: 1997-06-15 00:00:00.000 | Y33: MM | AE33: M | AH33: M056 | AI33: NULL | AJ33: NULL
A34: SOE MIN NAING | B34: Employee | C34: PRODUCTION DEPT | D34: MOLDER | E34: NG SENG CHUAN | G34: '011 39839864 | J34: NO 1 & 3 JLN MAHIR 5, TMN PERINDUSTRIAN CEMERLANG, ULU TIRAM, JOHOR. | L34: 81800 | M34: Malaysia | R34: Myanmar | U34: MF896706 | V34: M | W34: 1988-10-15 00:00:00.000 | Y34: MM | AE34: M | AH34: M032 | AI34: NULL | AJ34: NULL
A35: SOE MYINT NAING | B35: Employee | C35: PRODUCTION DEPT | D35: ASSEMBLE | E35: NG SENG CHUAN | G35: 011-27489478 | J35: NO 1 & 3 JALAN MAHIR 5, TAMAN PERINDUSTRIAN CEMERLANG, ULU TIRAM, JOHOR. | L35: 81800 | M35: Malaysia | R35: Myanmar | U35: MG564512 | V35: M | W35: 2002-09-18 00:00:00.000 | Y35: MM | AE35: S | AH35: M054 | AI35: NULL | AJ35: NULL
A36: TAN CHEK KA | B36: Employee | C36: STORE DEPT | D36: STORE SUPERVISOR | E36: NG SENG CHUAN | G36: 014 3860363 | J36: NO 87 JALAN BUNGA RAYA SIMPANG RENGGAM, JOHOR. | L36: 86200 | M36: Malaysia | R36: Malaysian | S36: 760906-01-7143 | V36: M | W36: 1976-09-06 00:00:00.000 | Y36: MA | AE36: S | AH36: L007 | AI36: NULL | AJ36: NULL
A37: TEEBA A/P THURAIRAJ | B37: Employee | C37: STORE DEPT | D37: STORE ASSISTANT | E37: SANTHIA A/P MANOGARAN | G37: 011-11247419 | J37: NO 66. JALAN TEMBIKAI 18, TAMAN KOTA MASAI, PASIR GUDANG, JOHOR. | L37: 81700 | M37: Malaysia | R37: Malaysian | S37: 981119-08-6982 | V37: F | W37: 1998-11-19 00:00:00.000 | Y37: MA | AE37: M | AH37: L053 | AI37: NULL | AJ37: NULL
A38: THET ZAW | B38: Employee | C38: PRODUCTION DEPT | D38: ASSEMBLE | E38: NG SENG CHUAN | G38: 011-28984097 | J38: NO. 1 & 3 JALAN MAHIR 5 TAMAN PERINDUSTRIAN CEMERLANG, ULU TIRAM, JOHOR. | M38: Malaysia | R38: Myanmar | U38: MH680607 | V38: M | W38: 1989-07-19 00:00:00.000 | Y38: MM | AE38: M | AH38: M058 | AI38: NULL | AJ38: NULL
A39: TIE LIN AUNG | B39: Employee | C39: PRODUCTION DEPT | D39: MELTER | E39: NULL | J39: NO. 1 & 3 JALAN MAHIR 5, TAMAN PERINDUSTRIAN CEMERLANG, ULU TIRAM,JOHOR. | L39: 81800 | M39: Malaysia | R39: Myanmar | U39: MI225867 | V39: M | W39: 1989-06-26 00:00:00.000 | Y39: MM | AE39: M | AH39: M062 | AI39: NULL | AJ39: NULL
A40: TIN YE AUNG | B40: Employee | C40: PRODUCTION DEPT | D40: MELTER | E40: MANIT SENNOK | G40: '011 61394051 | J40: NO. 1 & 3 JALAN MAHIR 5, TAMAN PERINDUSTRIAN CEMERLANG, | L40: 81800 | M40: Malaysia | R40: Myanmar | U40: MG569527 | V40: M | W40: 1991-12-22 00:00:00.000 | AE40: M | AH40: M050 | AI40: U THAN OO | AJ40: 9423728189
...

Sheet PT Lingjack
A1: Employee Name | B1: Employee Type | C1: Department | D1: Job Position | E1: Manager | F1: Work Email | G1: Work Phone | H1: Private Email | I1: Private Phone | J1: Private Street | K1: Private Street2 | L1: Private Zip | M1: Private Country | N1: Bank Account/Account Number | O1: Bank Account/Bank | P1: Bank Account/Currency | Q1: Private Car Plate | R1: Nationality (Country) | S1: Identification No | T1: SSN No | U1: Passport No | V1: Gender | W1: Date of Birth | X1: Place of Birth | Y1: Country of Birth | Z1: Field of Study | AA1: Visa No | AB1: Visa Expiration Date | AC1: Work Permit No | AD1: Work Permit Expiration Date | AE1: Marital Status | AF1: Number of Dependent Children | AG1: Hourly Cost | AH1: Badge ID | AI1: Contact Name | AJ1: Contact Phone
A2: FIKANATALIA | B2: Employee | C2: SALES-INDONESIA | D2: COUNTRY MGR | E2: LIM KOK KHENG | F2: fika@lingjack.com | M2: Indonesia | R2: Indonesian | S2: AAA | V2: Female | AE2: Married | AH2: 00028

Sheet lookup
A1: Job Position | B1: Hourly Cost
A2: ACCOUNTS ASS I | B2: 0
A3: ACCOUNTS EXEC III | B3: 0
A4: ASST ENGINEER | B4: 32
A5: ASST MGR | B5: 0
A6: ASST SUPERVISOR | B6: 40
A7: CLEANER | B7: 0
A8: CLERK | B8: 0
A9: CONSTRUCTION WORKER | B9: 19
A10: CS EXEC II | B10: 0
A11: CS EXEC III | B11: 0
A12: CS EXEC III | B12: 0
A13: DRIVER III | B13: 22
A14: ENGINEER | B14: 36
A15: FINANCE DIRECTOR | B15: 0
A16: HR ASSISTANT | B16: 0
A17: HR MANAGER | B17: 0
A18: LATHE SETTER-OPERATOR | B18: 19
A19: MANAGER | B19: 0
A20: MANAGING DIRECTOR | B20: 0
A21: PLANT DIRECTOR | B21: 0
A22: PLANT MANAGER | B22: 58
A23: PRODUCTION SPECIALIST I | B23: 24
A24: PRODUCTION SPECIALIST II | B24: 24
... A57: WELDER AND FLAME CUTTER | B57: 19
B58: 0
